2025-08-07 12:29:10 - app - INFO - User 'admin' initiated add_subject.
2025-08-07 12:29:15 - app - INFO - Subject '3e5cfb1649f29e4851393450e4eb85b7' added successfully by user 'admin'.
2025-08-07 13:45:55 - app - INFO - User 'admin' initiated add_subject.
2025-08-07 13:46:01 - app - INFO - Subject '01c05d12fe1fc8accfa59ca68870a1a7' added successfully by user 'admin'.
2025-08-07 14:10:49 - app - INFO - User 'admin' initiated add_subject.
2025-08-07 14:16:37 - app - INFO - User 'admin' initiated add_subject.
2025-08-07 14:59:35 - app - INFO - Auth user 'admin' cleared 10 records for session user '134'.
2025-08-07 10:26:58 - app - ERROR - Exception on /api/register [POST]
Traceback (most recent call last):
  File "/usr/local/lib/python3.11/site-packages/sqlalchemy/engine/base.py", line 143, in __init__
    self._dbapi_connection = engine.raw_connection()
                             ^^^^^^^^^^^^^^^^^^^^^^^
  File "/usr/local/lib/python3.11/site-packages/sqlalchemy/engine/base.py", line 3295, in raw_connection
    return self.pool.connect()
           ^^^^^^^^^^^^^^^^^^^
  File "/usr/local/lib/python3.11/site-packages/sqlalchemy/pool/base.py", line 447, in connect
    return _ConnectionFairy._checkout(self)
           ^^^^^^^^^^^^^^^^^^^^^^^^^^^^^^^^
  File "/usr/local/lib/python3.11/site-packages/sqlalchemy/pool/base.py", line 1264, in _checkout
    fairy = _ConnectionRecord.checkout(pool)
            ^^^^^^^^^^^^^^^^^^^^^^^^^^^^^^^^
  File "/usr/local/lib/python3.11/site-packages/sqlalchemy/pool/base.py", line 711, in checkout
    rec = pool._do_get()
          ^^^^^^^^^^^^^^
  File "/usr/local/lib/python3.11/site-packages/sqlalchemy/pool/impl.py", line 177, in _do_get
    with util.safe_reraise():
  File "/usr/local/lib/python3.11/site-packages/sqlalchemy/util/langhelpers.py", line 224, in __exit__
    raise exc_value.with_traceback(exc_tb)
  File "/usr/local/lib/python3.11/site-packages/sqlalchemy/pool/impl.py", line 175, in _do_get
    return self._create_connection()
           ^^^^^^^^^^^^^^^^^^^^^^^^^
  File "/usr/local/lib/python3.11/site-packages/sqlalchemy/pool/base.py", line 388, in _create_connection
    return _ConnectionRecord(self)
           ^^^^^^^^^^^^^^^^^^^^^^^
  File "/usr/local/lib/python3.11/site-packages/sqlalchemy/pool/base.py", line 673, in __init__
    self.__connect()
  File "/usr/local/lib/python3.11/site-packages/sqlalchemy/pool/base.py", line 899, in __connect
    with util.safe_reraise():
  File "/usr/local/lib/python3.11/site-packages/sqlalchemy/util/langhelpers.py", line 224, in __exit__
    raise exc_value.with_traceback(exc_tb)
  File "/usr/local/lib/python3.11/site-packages/sqlalchemy/pool/base.py", line 895, in __connect
    self.dbapi_connection = connection = pool._invoke_creator(self)
                                         ^^^^^^^^^^^^^^^^^^^^^^^^^^
  File "/usr/local/lib/python3.11/site-packages/sqlalchemy/engine/create.py", line 646, in connect
    return dialect.connect(*cargs, **cparams)
           ^^^^^^^^^^^^^^^^^^^^^^^^^^^^^^^^^^
  File "/usr/local/lib/python3.11/site-packages/sqlalchemy/engine/default.py", line 626, in connect
    return self.loaded_dbapi.connect(*cargs, **cparams)  # type: ignore[no-any-return]  # NOQA: E501
           ^^^^^^^^^^^^^^^^^^^^^^^^^^^^^^^^^^^^^^^^^^^^
  File "/usr/local/lib/python3.11/site-packages/psycopg2/__init__.py", line 122, in connect
    conn = _connect(dsn, connection_factory=connection_factory, **kwasync)
           ^^^^^^^^^^^^^^^^^^^^^^^^^^^^^^^^^^^^^^^^^^^^^^^^^^^^^^^^^^^^^^^
psycopg2.OperationalError: connection to server at "localhost" (::1), port 5432 failed: Connection refused
	Is the server running on that host and accepting TCP/IP connections?
connection to server at "localhost" (127.0.0.1), port 5432 failed: Connection refused
	Is the server running on that host and accepting TCP/IP connections?


The above exception was the direct cause of the following exception:

Traceback (most recent call last):
  File "/usr/local/lib/python3.11/site-packages/flask/app.py", line 1511, in wsgi_app
    response = self.full_dispatch_request()
               ^^^^^^^^^^^^^^^^^^^^^^^^^^^^
  File "/usr/local/lib/python3.11/site-packages/flask/app.py", line 919, in full_dispatch_request
    rv = self.handle_user_exception(e)
         ^^^^^^^^^^^^^^^^^^^^^^^^^^^^^
  File "/usr/local/lib/python3.11/site-packages/flask/app.py", line 917, in full_dispatch_request
    rv = self.dispatch_request()
         ^^^^^^^^^^^^^^^^^^^^^^^
  File "/usr/local/lib/python3.11/site-packages/flask/app.py", line 902, in dispatch_request
    return self.ensure_sync(self.view_functions[rule.endpoint])(**view_args)  # type: ignore[no-any-return]
           ^^^^^^^^^^^^^^^^^^^^^^^^^^^^^^^^^^^^^^^^^^^^^^^^^^^^^^^^^^^^^^^^^
  File "/usr/local/lib/python3.11/site-packages/flask_limiter/extension.py", line 1314, in __inner
    return cast(R, flask.current_app.ensure_sync(obj)(*a, **k))
                   ^^^^^^^^^^^^^^^^^^^^^^^^^^^^^^^^^^^^^^^^^^^
  File "/app/app/routes.py", line 36, in register
    if User.query.filter_by(username=username).first():
       ^^^^^^^^^^^^^^^^^^^^^^^^^^^^^^^^^^^^^^^^^^^^^^^
  File "/usr/local/lib/python3.11/site-packages/sqlalchemy/orm/query.py", line 2759, in first
    return self.limit(1)._iter().first()  # type: ignore
           ^^^^^^^^^^^^^^^^^^^^^
  File "/usr/local/lib/python3.11/site-packages/sqlalchemy/orm/query.py", line 2857, in _iter
    result: Union[ScalarResult[_T], Result[_T]] = self.session.execute(
                                                  ^^^^^^^^^^^^^^^^^^^^^
  File "/usr/local/lib/python3.11/site-packages/sqlalchemy/orm/session.py", line 2365, in execute
    return self._execute_internal(
           ^^^^^^^^^^^^^^^^^^^^^^^
  File "/usr/local/lib/python3.11/site-packages/sqlalchemy/orm/session.py", line 2241, in _execute_internal
    conn = self._connection_for_bind(bind)
           ^^^^^^^^^^^^^^^^^^^^^^^^^^^^^^^
  File "/usr/local/lib/python3.11/site-packages/sqlalchemy/orm/session.py", line 2110, in _connection_for_bind
    return trans._connection_for_bind(engine, execution_options)
           ^^^^^^^^^^^^^^^^^^^^^^^^^^^^^^^^^^^^^^^^^^^^^^^^^^^^^
  File "<string>", line 2, in _connection_for_bind
  File "/usr/local/lib/python3.11/site-packages/sqlalchemy/orm/state_changes.py", line 137, in _go
    ret_value = fn(self, *arg, **kw)
                ^^^^^^^^^^^^^^^^^^^^
  File "/usr/local/lib/python3.11/site-packages/sqlalchemy/orm/session.py", line 1189, in _connection_for_bind
    conn = bind.connect()
           ^^^^^^^^^^^^^^
  File "/usr/local/lib/python3.11/site-packages/sqlalchemy/engine/base.py", line 3271, in connect
    return self._connection_cls(self)
           ^^^^^^^^^^^^^^^^^^^^^^^^^^
  File "/usr/local/lib/python3.11/site-packages/sqlalchemy/engine/base.py", line 145, in __init__
    Connection._handle_dbapi_exception_noconnection(
  File "/usr/local/lib/python3.11/site-packages/sqlalchemy/engine/base.py", line 2434, in _handle_dbapi_exception_noconnection
    raise sqlalchemy_exception.with_traceback(exc_info[2]) from e
  File "/usr/local/lib/python3.11/site-packages/sqlalchemy/engine/base.py", line 143, in __init__
    self._dbapi_connection = engine.raw_connection()
                             ^^^^^^^^^^^^^^^^^^^^^^^
  File "/usr/local/lib/python3.11/site-packages/sqlalchemy/engine/base.py", line 3295, in raw_connection
    return self.pool.connect()
           ^^^^^^^^^^^^^^^^^^^
  File "/usr/local/lib/python3.11/site-packages/sqlalchemy/pool/base.py", line 447, in connect
    return _ConnectionFairy._checkout(self)
           ^^^^^^^^^^^^^^^^^^^^^^^^^^^^^^^^
  File "/usr/local/lib/python3.11/site-packages/sqlalchemy/pool/base.py", line 1264, in _checkout
    fairy = _ConnectionRecord.checkout(pool)
            ^^^^^^^^^^^^^^^^^^^^^^^^^^^^^^^^
  File "/usr/local/lib/python3.11/site-packages/sqlalchemy/pool/base.py", line 711, in checkout
    rec = pool._do_get()
          ^^^^^^^^^^^^^^
  File "/usr/local/lib/python3.11/site-packages/sqlalchemy/pool/impl.py", line 177, in _do_get
    with util.safe_reraise():
  File "/usr/local/lib/python3.11/site-packages/sqlalchemy/util/langhelpers.py", line 224, in __exit__
    raise exc_value.with_traceback(exc_tb)
  File "/usr/local/lib/python3.11/site-packages/sqlalchemy/pool/impl.py", line 175, in _do_get
    return self._create_connection()
           ^^^^^^^^^^^^^^^^^^^^^^^^^
  File "/usr/local/lib/python3.11/site-packages/sqlalchemy/pool/base.py", line 388, in _create_connection
    return _ConnectionRecord(self)
           ^^^^^^^^^^^^^^^^^^^^^^^
  File "/usr/local/lib/python3.11/site-packages/sqlalchemy/pool/base.py", line 673, in __init__
    self.__connect()
  File "/usr/local/lib/python3.11/site-packages/sqlalchemy/pool/base.py", line 899, in __connect
    with util.safe_reraise():
  File "/usr/local/lib/python3.11/site-packages/sqlalchemy/util/langhelpers.py", line 224, in __exit__
    raise exc_value.with_traceback(exc_tb)
  File "/usr/local/lib/python3.11/site-packages/sqlalchemy/pool/base.py", line 895, in __connect
    self.dbapi_connection = connection = pool._invoke_creator(self)
                                         ^^^^^^^^^^^^^^^^^^^^^^^^^^
  File "/usr/local/lib/python3.11/site-packages/sqlalchemy/engine/create.py", line 646, in connect
    return dialect.connect(*cargs, **cparams)
           ^^^^^^^^^^^^^^^^^^^^^^^^^^^^^^^^^^
  File "/usr/local/lib/python3.11/site-packages/sqlalchemy/engine/default.py", line 626, in connect
    return self.loaded_dbapi.connect(*cargs, **cparams)  # type: ignore[no-any-return]  # NOQA: E501
           ^^^^^^^^^^^^^^^^^^^^^^^^^^^^^^^^^^^^^^^^^^^^
  File "/usr/local/lib/python3.11/site-packages/psycopg2/__init__.py", line 122, in connect
    conn = _connect(dsn, connection_factory=connection_factory, **kwasync)
           ^^^^^^^^^^^^^^^^^^^^^^^^^^^^^^^^^^^^^^^^^^^^^^^^^^^^^^^^^^^^^^^
sqlalchemy.exc.OperationalError: (psycopg2.OperationalError) connection to server at "localhost" (::1), port 5432 failed: Connection refused
	Is the server running on that host and accepting TCP/IP connections?
connection to server at "localhost" (127.0.0.1), port 5432 failed: Connection refused
	Is the server running on that host and accepting TCP/IP connections?

(Background on this error at: https://sqlalche.me/e/20/e3q8)
2025-08-11 10:21:28 - app - ERROR - Exception on /admin/course/new/ [POST]
Traceback (most recent call last):
  File "C:\Users\ashiq\AppData\Local\Programs\Python\Python312\Lib\site-packages\sqlalchemy\engine\base.py", line 1963, in _exec_single_context
    self.dialect.do_execute(
  File "C:\Users\ashiq\AppData\Local\Programs\Python\Python312\Lib\site-packages\sqlalchemy\engine\default.py", line 943, in do_execute
    cursor.execute(statement, parameters)
psycopg2.errors.NotNullViolation: null value in column "syllabus_id" of relation "courses" violates not-null constraint
DETAIL:  Failing row contains (1, english, null, null).


The above exception was the direct cause of the following exception:

Traceback (most recent call last):
  File "C:\Users\ashiq\AppData\Local\Programs\Python\Python312\Lib\site-packages\flask_admin\contrib\sqla\view.py", line 1163, in create_model
    self.session.commit()
  File "C:\Users\ashiq\AppData\Local\Programs\Python\Python312\Lib\site-packages\sqlalchemy\orm\scoping.py", line 599, in commit
    return self._proxied.commit()
           ^^^^^^^^^^^^^^^^^^^^^^
  File "C:\Users\ashiq\AppData\Local\Programs\Python\Python312\Lib\site-packages\sqlalchemy\orm\session.py", line 2032, in commit
    trans.commit(_to_root=True)
  File "<string>", line 2, in commit
  File "C:\Users\ashiq\AppData\Local\Programs\Python\Python312\Lib\site-packages\sqlalchemy\orm\state_changes.py", line 139, in _go
    ret_value = fn(self, *arg, **kw)
                ^^^^^^^^^^^^^^^^^^^^
  File "C:\Users\ashiq\AppData\Local\Programs\Python\Python312\Lib\site-packages\sqlalchemy\orm\session.py", line 1313, in commit
    self._prepare_impl()
  File "<string>", line 2, in _prepare_impl
  File "C:\Users\ashiq\AppData\Local\Programs\Python\Python312\Lib\site-packages\sqlalchemy\orm\state_changes.py", line 139, in _go
    ret_value = fn(self, *arg, **kw)
                ^^^^^^^^^^^^^^^^^^^^
  File "C:\Users\ashiq\AppData\Local\Programs\Python\Python312\Lib\site-packages\sqlalchemy\orm\session.py", line 1288, in _prepare_impl
    self.session.flush()
  File "C:\Users\ashiq\AppData\Local\Programs\Python\Python312\Lib\site-packages\sqlalchemy\orm\session.py", line 4345, in flush
    self._flush(objects)
  File "C:\Users\ashiq\AppData\Local\Programs\Python\Python312\Lib\site-packages\sqlalchemy\orm\session.py", line 4480, in _flush
    with util.safe_reraise():
  File "C:\Users\ashiq\AppData\Local\Programs\Python\Python312\Lib\site-packages\sqlalchemy\util\langhelpers.py", line 224, in __exit__
    raise exc_value.with_traceback(exc_tb)
  File "C:\Users\ashiq\AppData\Local\Programs\Python\Python312\Lib\site-packages\sqlalchemy\orm\session.py", line 4441, in _flush
    flush_context.execute()
  File "C:\Users\ashiq\AppData\Local\Programs\Python\Python312\Lib\site-packages\sqlalchemy\orm\unitofwork.py", line 466, in execute
    rec.execute(self)
  File "C:\Users\ashiq\AppData\Local\Programs\Python\Python312\Lib\site-packages\sqlalchemy\orm\unitofwork.py", line 642, in execute
    util.preloaded.orm_persistence.save_obj(
  File "C:\Users\ashiq\AppData\Local\Programs\Python\Python312\Lib\site-packages\sqlalchemy\orm\persistence.py", line 93, in save_obj
    _emit_insert_statements(
  File "C:\Users\ashiq\AppData\Local\Programs\Python\Python312\Lib\site-packages\sqlalchemy\orm\persistence.py", line 1233, in _emit_insert_statements
    result = connection.execute(
             ^^^^^^^^^^^^^^^^^^^
  File "C:\Users\ashiq\AppData\Local\Programs\Python\Python312\Lib\site-packages\sqlalchemy\engine\base.py", line 1415, in execute
    return meth(
           ^^^^^
  File "C:\Users\ashiq\AppData\Local\Programs\Python\Python312\Lib\site-packages\sqlalchemy\sql\elements.py", line 523, in _execute_on_connection
    return connection._execute_clauseelement(
           ^^^^^^^^^^^^^^^^^^^^^^^^^^^^^^^^^^
  File "C:\Users\ashiq\AppData\Local\Programs\Python\Python312\Lib\site-packages\sqlalchemy\engine\base.py", line 1637, in _execute_clauseelement
    ret = self._execute_context(
          ^^^^^^^^^^^^^^^^^^^^^^
  File "C:\Users\ashiq\AppData\Local\Programs\Python\Python312\Lib\site-packages\sqlalchemy\engine\base.py", line 1842, in _execute_context
    return self._exec_single_context(
           ^^^^^^^^^^^^^^^^^^^^^^^^^^
  File "C:\Users\ashiq\AppData\Local\Programs\Python\Python312\Lib\site-packages\sqlalchemy\engine\base.py", line 1982, in _exec_single_context
    self._handle_dbapi_exception(
  File "C:\Users\ashiq\AppData\Local\Programs\Python\Python312\Lib\site-packages\sqlalchemy\engine\base.py", line 2351, in _handle_dbapi_exception
    raise sqlalchemy_exception.with_traceback(exc_info[2]) from e
  File "C:\Users\ashiq\AppData\Local\Programs\Python\Python312\Lib\site-packages\sqlalchemy\engine\base.py", line 1963, in _exec_single_context
    self.dialect.do_execute(
  File "C:\Users\ashiq\AppData\Local\Programs\Python\Python312\Lib\site-packages\sqlalchemy\engine\default.py", line 943, in do_execute
    cursor.execute(statement, parameters)
sqlalchemy.exc.IntegrityError: (psycopg2.errors.NotNullViolation) null value in column "syllabus_id" of relation "courses" violates not-null constraint
DETAIL:  Failing row contains (1, english, null, null).

[SQL: INSERT INTO courses (name) VALUES (%(name)s) RETURNING courses.id]
[parameters: {'name': 'english'}]
(Background on this error at: https://sqlalche.me/e/20/gkpj)

During handling of the above exception, another exception occurred:

Traceback (most recent call last):
  File "C:\Users\ashiq\AppData\Local\Programs\Python\Python312\Lib\site-packages\flask\app.py", line 2190, in wsgi_app
    response = self.full_dispatch_request()
               ^^^^^^^^^^^^^^^^^^^^^^^^^^^^
  File "C:\Users\ashiq\AppData\Local\Programs\Python\Python312\Lib\site-packages\flask\app.py", line 1486, in full_dispatch_request
    rv = self.handle_user_exception(e)
         ^^^^^^^^^^^^^^^^^^^^^^^^^^^^^
  File "C:\Users\ashiq\AppData\Local\Programs\Python\Python312\Lib\site-packages\flask\app.py", line 1484, in full_dispatch_request
    rv = self.dispatch_request()
         ^^^^^^^^^^^^^^^^^^^^^^^
  File "C:\Users\ashiq\AppData\Local\Programs\Python\Python312\Lib\site-packages\flask\app.py", line 1469, in dispatch_request
    return self.ensure_sync(self.view_functions[rule.endpoint])(**view_args)
           ^^^^^^^^^^^^^^^^^^^^^^^^^^^^^^^^^^^^^^^^^^^^^^^^^^^^^^^^^^^^^^^^^
  File "C:\Users\ashiq\AppData\Local\Programs\Python\Python312\Lib\site-packages\flask_admin\base.py", line 69, in inner
    return self._run_view(f, *args, **kwargs)
           ^^^^^^^^^^^^^^^^^^^^^^^^^^^^^^^^^^
  File "C:\Users\ashiq\AppData\Local\Programs\Python\Python312\Lib\site-packages\flask_admin\base.py", line 369, in _run_view
    return fn(self, *args, **kwargs)
           ^^^^^^^^^^^^^^^^^^^^^^^^^
  File "C:\Users\ashiq\AppData\Local\Programs\Python\Python312\Lib\site-packages\flask_admin\model\base.py", line 2100, in create_view
    model = self.create_model(form)
            ^^^^^^^^^^^^^^^^^^^^^^^
  File "C:\Users\ashiq\AppData\Local\Programs\Python\Python312\Lib\site-packages\flask_admin\contrib\sqla\view.py", line 1165, in create_model
    if not self.handle_view_exception(ex):
           ^^^^^^^^^^^^^^^^^^^^^^^^^^^^^^
  File "C:\Users\ashiq\AppData\Local\Programs\Python\Python312\Lib\site-packages\flask_admin\contrib\sqla\view.py", line 1130, in handle_view_exception
    flash(gettext('Integrity error. %(message)s', message=text_type(exc)), 'error')
  File "C:\Users\ashiq\AppData\Local\Programs\Python\Python312\Lib\site-packages\flask\helpers.py", line 328, in flash
    session["_flashes"] = flashes
    ~~~~~~~^^^^^^^^^^^^
  File "C:\Users\ashiq\AppData\Local\Programs\Python\Python312\Lib\site-packages\flask\sessions.py", line 97, in _fail
    raise RuntimeError(
RuntimeError: The session is unavailable because no secret key was set.  Set the secret_key on the application to something unique and secret.
2025-08-11 10:26:12 - app - ERROR - Exception on /admin/course/new/ [POST]
Traceback (most recent call last):
  File "C:\Users\ashiq\AppData\Local\Programs\Python\Python312\Lib\site-packages\sqlalchemy\engine\base.py", line 1963, in _exec_single_context
    self.dialect.do_execute(
  File "C:\Users\ashiq\AppData\Local\Programs\Python\Python312\Lib\site-packages\sqlalchemy\engine\default.py", line 943, in do_execute
    cursor.execute(statement, parameters)
psycopg2.errors.NotNullViolation: null value in column "syllabus_id" of relation "courses" violates not-null constraint
DETAIL:  Failing row contains (2, english, null, null).


The above exception was the direct cause of the following exception:

Traceback (most recent call last):
  File "C:\Users\ashiq\AppData\Local\Programs\Python\Python312\Lib\site-packages\flask_admin\contrib\sqla\view.py", line 1163, in create_model
    self.session.commit()
  File "C:\Users\ashiq\AppData\Local\Programs\Python\Python312\Lib\site-packages\sqlalchemy\orm\scoping.py", line 599, in commit
    return self._proxied.commit()
           ^^^^^^^^^^^^^^^^^^^^^^
  File "C:\Users\ashiq\AppData\Local\Programs\Python\Python312\Lib\site-packages\sqlalchemy\orm\session.py", line 2032, in commit
    trans.commit(_to_root=True)
  File "<string>", line 2, in commit
  File "C:\Users\ashiq\AppData\Local\Programs\Python\Python312\Lib\site-packages\sqlalchemy\orm\state_changes.py", line 139, in _go
    ret_value = fn(self, *arg, **kw)
                ^^^^^^^^^^^^^^^^^^^^
  File "C:\Users\ashiq\AppData\Local\Programs\Python\Python312\Lib\site-packages\sqlalchemy\orm\session.py", line 1313, in commit
    self._prepare_impl()
  File "<string>", line 2, in _prepare_impl
  File "C:\Users\ashiq\AppData\Local\Programs\Python\Python312\Lib\site-packages\sqlalchemy\orm\state_changes.py", line 139, in _go
    ret_value = fn(self, *arg, **kw)
                ^^^^^^^^^^^^^^^^^^^^
  File "C:\Users\ashiq\AppData\Local\Programs\Python\Python312\Lib\site-packages\sqlalchemy\orm\session.py", line 1288, in _prepare_impl
    self.session.flush()
  File "C:\Users\ashiq\AppData\Local\Programs\Python\Python312\Lib\site-packages\sqlalchemy\orm\session.py", line 4345, in flush
    self._flush(objects)
  File "C:\Users\ashiq\AppData\Local\Programs\Python\Python312\Lib\site-packages\sqlalchemy\orm\session.py", line 4480, in _flush
    with util.safe_reraise():
  File "C:\Users\ashiq\AppData\Local\Programs\Python\Python312\Lib\site-packages\sqlalchemy\util\langhelpers.py", line 224, in __exit__
    raise exc_value.with_traceback(exc_tb)
  File "C:\Users\ashiq\AppData\Local\Programs\Python\Python312\Lib\site-packages\sqlalchemy\orm\session.py", line 4441, in _flush
    flush_context.execute()
  File "C:\Users\ashiq\AppData\Local\Programs\Python\Python312\Lib\site-packages\sqlalchemy\orm\unitofwork.py", line 466, in execute
    rec.execute(self)
  File "C:\Users\ashiq\AppData\Local\Programs\Python\Python312\Lib\site-packages\sqlalchemy\orm\unitofwork.py", line 642, in execute
    util.preloaded.orm_persistence.save_obj(
  File "C:\Users\ashiq\AppData\Local\Programs\Python\Python312\Lib\site-packages\sqlalchemy\orm\persistence.py", line 93, in save_obj
    _emit_insert_statements(
  File "C:\Users\ashiq\AppData\Local\Programs\Python\Python312\Lib\site-packages\sqlalchemy\orm\persistence.py", line 1233, in _emit_insert_statements
    result = connection.execute(
             ^^^^^^^^^^^^^^^^^^^
  File "C:\Users\ashiq\AppData\Local\Programs\Python\Python312\Lib\site-packages\sqlalchemy\engine\base.py", line 1415, in execute
    return meth(
           ^^^^^
  File "C:\Users\ashiq\AppData\Local\Programs\Python\Python312\Lib\site-packages\sqlalchemy\sql\elements.py", line 523, in _execute_on_connection
    return connection._execute_clauseelement(
           ^^^^^^^^^^^^^^^^^^^^^^^^^^^^^^^^^^
  File "C:\Users\ashiq\AppData\Local\Programs\Python\Python312\Lib\site-packages\sqlalchemy\engine\base.py", line 1637, in _execute_clauseelement
    ret = self._execute_context(
          ^^^^^^^^^^^^^^^^^^^^^^
  File "C:\Users\ashiq\AppData\Local\Programs\Python\Python312\Lib\site-packages\sqlalchemy\engine\base.py", line 1842, in _execute_context
    return self._exec_single_context(
           ^^^^^^^^^^^^^^^^^^^^^^^^^^
  File "C:\Users\ashiq\AppData\Local\Programs\Python\Python312\Lib\site-packages\sqlalchemy\engine\base.py", line 1982, in _exec_single_context
    self._handle_dbapi_exception(
  File "C:\Users\ashiq\AppData\Local\Programs\Python\Python312\Lib\site-packages\sqlalchemy\engine\base.py", line 2351, in _handle_dbapi_exception
    raise sqlalchemy_exception.with_traceback(exc_info[2]) from e
  File "C:\Users\ashiq\AppData\Local\Programs\Python\Python312\Lib\site-packages\sqlalchemy\engine\base.py", line 1963, in _exec_single_context
    self.dialect.do_execute(
  File "C:\Users\ashiq\AppData\Local\Programs\Python\Python312\Lib\site-packages\sqlalchemy\engine\default.py", line 943, in do_execute
    cursor.execute(statement, parameters)
sqlalchemy.exc.IntegrityError: (psycopg2.errors.NotNullViolation) null value in column "syllabus_id" of relation "courses" violates not-null constraint
DETAIL:  Failing row contains (2, english, null, null).

[SQL: INSERT INTO courses (name) VALUES (%(name)s) RETURNING courses.id]
[parameters: {'name': 'english'}]
(Background on this error at: https://sqlalche.me/e/20/gkpj)

During handling of the above exception, another exception occurred:

Traceback (most recent call last):
  File "C:\Users\ashiq\AppData\Local\Programs\Python\Python312\Lib\site-packages\flask\app.py", line 2190, in wsgi_app
    response = self.full_dispatch_request()
               ^^^^^^^^^^^^^^^^^^^^^^^^^^^^
  File "C:\Users\ashiq\AppData\Local\Programs\Python\Python312\Lib\site-packages\flask\app.py", line 1486, in full_dispatch_request
    rv = self.handle_user_exception(e)
         ^^^^^^^^^^^^^^^^^^^^^^^^^^^^^
  File "C:\Users\ashiq\AppData\Local\Programs\Python\Python312\Lib\site-packages\flask\app.py", line 1484, in full_dispatch_request
    rv = self.dispatch_request()
         ^^^^^^^^^^^^^^^^^^^^^^^
  File "C:\Users\ashiq\AppData\Local\Programs\Python\Python312\Lib\site-packages\flask\app.py", line 1469, in dispatch_request
    return self.ensure_sync(self.view_functions[rule.endpoint])(**view_args)
           ^^^^^^^^^^^^^^^^^^^^^^^^^^^^^^^^^^^^^^^^^^^^^^^^^^^^^^^^^^^^^^^^^
  File "C:\Users\ashiq\AppData\Local\Programs\Python\Python312\Lib\site-packages\flask_admin\base.py", line 69, in inner
    return self._run_view(f, *args, **kwargs)
           ^^^^^^^^^^^^^^^^^^^^^^^^^^^^^^^^^^
  File "C:\Users\ashiq\AppData\Local\Programs\Python\Python312\Lib\site-packages\flask_admin\base.py", line 369, in _run_view
    return fn(self, *args, **kwargs)
           ^^^^^^^^^^^^^^^^^^^^^^^^^
  File "C:\Users\ashiq\AppData\Local\Programs\Python\Python312\Lib\site-packages\flask_admin\model\base.py", line 2100, in create_view
    model = self.create_model(form)
            ^^^^^^^^^^^^^^^^^^^^^^^
  File "C:\Users\ashiq\AppData\Local\Programs\Python\Python312\Lib\site-packages\flask_admin\contrib\sqla\view.py", line 1165, in create_model
    if not self.handle_view_exception(ex):
           ^^^^^^^^^^^^^^^^^^^^^^^^^^^^^^
  File "C:\Users\ashiq\AppData\Local\Programs\Python\Python312\Lib\site-packages\flask_admin\contrib\sqla\view.py", line 1130, in handle_view_exception
    flash(gettext('Integrity error. %(message)s', message=text_type(exc)), 'error')
  File "C:\Users\ashiq\AppData\Local\Programs\Python\Python312\Lib\site-packages\flask\helpers.py", line 328, in flash
    session["_flashes"] = flashes
    ~~~~~~~^^^^^^^^^^^^
  File "C:\Users\ashiq\AppData\Local\Programs\Python\Python312\Lib\site-packages\flask\sessions.py", line 97, in _fail
    raise RuntimeError(
RuntimeError: The session is unavailable because no secret key was set.  Set the secret_key on the application to something unique and secret.
2025-08-11 10:55:12 - app - ERROR - Exception on /admin/course/new/ [POST]
Traceback (most recent call last):
  File "C:\Users\ashiq\AppData\Local\Programs\Python\Python312\Lib\site-packages\sqlalchemy\engine\base.py", line 1963, in _exec_single_context
    self.dialect.do_execute(
  File "C:\Users\ashiq\AppData\Local\Programs\Python\Python312\Lib\site-packages\sqlalchemy\engine\default.py", line 943, in do_execute
    cursor.execute(statement, parameters)
psycopg2.errors.NotNullViolation: null value in column "syllabus_id" of relation "courses" violates not-null constraint
DETAIL:  Failing row contains (3, english, null, null).


The above exception was the direct cause of the following exception:

Traceback (most recent call last):
  File "C:\Users\ashiq\AppData\Local\Programs\Python\Python312\Lib\site-packages\flask_admin\contrib\sqla\view.py", line 1163, in create_model
    self.session.commit()
  File "C:\Users\ashiq\AppData\Local\Programs\Python\Python312\Lib\site-packages\sqlalchemy\orm\scoping.py", line 599, in commit
    return self._proxied.commit()
           ^^^^^^^^^^^^^^^^^^^^^^
  File "C:\Users\ashiq\AppData\Local\Programs\Python\Python312\Lib\site-packages\sqlalchemy\orm\session.py", line 2032, in commit
    trans.commit(_to_root=True)
  File "<string>", line 2, in commit
  File "C:\Users\ashiq\AppData\Local\Programs\Python\Python312\Lib\site-packages\sqlalchemy\orm\state_changes.py", line 139, in _go
    ret_value = fn(self, *arg, **kw)
                ^^^^^^^^^^^^^^^^^^^^
  File "C:\Users\ashiq\AppData\Local\Programs\Python\Python312\Lib\site-packages\sqlalchemy\orm\session.py", line 1313, in commit
    self._prepare_impl()
  File "<string>", line 2, in _prepare_impl
  File "C:\Users\ashiq\AppData\Local\Programs\Python\Python312\Lib\site-packages\sqlalchemy\orm\state_changes.py", line 139, in _go
    ret_value = fn(self, *arg, **kw)
                ^^^^^^^^^^^^^^^^^^^^
  File "C:\Users\ashiq\AppData\Local\Programs\Python\Python312\Lib\site-packages\sqlalchemy\orm\session.py", line 1288, in _prepare_impl
    self.session.flush()
  File "C:\Users\ashiq\AppData\Local\Programs\Python\Python312\Lib\site-packages\sqlalchemy\orm\session.py", line 4345, in flush
    self._flush(objects)
  File "C:\Users\ashiq\AppData\Local\Programs\Python\Python312\Lib\site-packages\sqlalchemy\orm\session.py", line 4480, in _flush
    with util.safe_reraise():
  File "C:\Users\ashiq\AppData\Local\Programs\Python\Python312\Lib\site-packages\sqlalchemy\util\langhelpers.py", line 224, in __exit__
    raise exc_value.with_traceback(exc_tb)
  File "C:\Users\ashiq\AppData\Local\Programs\Python\Python312\Lib\site-packages\sqlalchemy\orm\session.py", line 4441, in _flush
    flush_context.execute()
  File "C:\Users\ashiq\AppData\Local\Programs\Python\Python312\Lib\site-packages\sqlalchemy\orm\unitofwork.py", line 466, in execute
    rec.execute(self)
  File "C:\Users\ashiq\AppData\Local\Programs\Python\Python312\Lib\site-packages\sqlalchemy\orm\unitofwork.py", line 642, in execute
    util.preloaded.orm_persistence.save_obj(
  File "C:\Users\ashiq\AppData\Local\Programs\Python\Python312\Lib\site-packages\sqlalchemy\orm\persistence.py", line 93, in save_obj
    _emit_insert_statements(
  File "C:\Users\ashiq\AppData\Local\Programs\Python\Python312\Lib\site-packages\sqlalchemy\orm\persistence.py", line 1233, in _emit_insert_statements
    result = connection.execute(
             ^^^^^^^^^^^^^^^^^^^
  File "C:\Users\ashiq\AppData\Local\Programs\Python\Python312\Lib\site-packages\sqlalchemy\engine\base.py", line 1415, in execute
    return meth(
           ^^^^^
  File "C:\Users\ashiq\AppData\Local\Programs\Python\Python312\Lib\site-packages\sqlalchemy\sql\elements.py", line 523, in _execute_on_connection
    return connection._execute_clauseelement(
           ^^^^^^^^^^^^^^^^^^^^^^^^^^^^^^^^^^
  File "C:\Users\ashiq\AppData\Local\Programs\Python\Python312\Lib\site-packages\sqlalchemy\engine\base.py", line 1637, in _execute_clauseelement
    ret = self._execute_context(
          ^^^^^^^^^^^^^^^^^^^^^^
  File "C:\Users\ashiq\AppData\Local\Programs\Python\Python312\Lib\site-packages\sqlalchemy\engine\base.py", line 1842, in _execute_context
    return self._exec_single_context(
           ^^^^^^^^^^^^^^^^^^^^^^^^^^
  File "C:\Users\ashiq\AppData\Local\Programs\Python\Python312\Lib\site-packages\sqlalchemy\engine\base.py", line 1982, in _exec_single_context
    self._handle_dbapi_exception(
  File "C:\Users\ashiq\AppData\Local\Programs\Python\Python312\Lib\site-packages\sqlalchemy\engine\base.py", line 2351, in _handle_dbapi_exception
    raise sqlalchemy_exception.with_traceback(exc_info[2]) from e
  File "C:\Users\ashiq\AppData\Local\Programs\Python\Python312\Lib\site-packages\sqlalchemy\engine\base.py", line 1963, in _exec_single_context
    self.dialect.do_execute(
  File "C:\Users\ashiq\AppData\Local\Programs\Python\Python312\Lib\site-packages\sqlalchemy\engine\default.py", line 943, in do_execute
    cursor.execute(statement, parameters)
sqlalchemy.exc.IntegrityError: (psycopg2.errors.NotNullViolation) null value in column "syllabus_id" of relation "courses" violates not-null constraint
DETAIL:  Failing row contains (3, english, null, null).

[SQL: INSERT INTO courses (name) VALUES (%(name)s) RETURNING courses.id]
[parameters: {'name': 'english'}]
(Background on this error at: https://sqlalche.me/e/20/gkpj)

During handling of the above exception, another exception occurred:

Traceback (most recent call last):
  File "C:\Users\ashiq\AppData\Local\Programs\Python\Python312\Lib\site-packages\flask\app.py", line 2190, in wsgi_app
    response = self.full_dispatch_request()
               ^^^^^^^^^^^^^^^^^^^^^^^^^^^^
  File "C:\Users\ashiq\AppData\Local\Programs\Python\Python312\Lib\site-packages\flask\app.py", line 1486, in full_dispatch_request
    rv = self.handle_user_exception(e)
         ^^^^^^^^^^^^^^^^^^^^^^^^^^^^^
  File "C:\Users\ashiq\AppData\Local\Programs\Python\Python312\Lib\site-packages\flask\app.py", line 1484, in full_dispatch_request
    rv = self.dispatch_request()
         ^^^^^^^^^^^^^^^^^^^^^^^
  File "C:\Users\ashiq\AppData\Local\Programs\Python\Python312\Lib\site-packages\flask\app.py", line 1469, in dispatch_request
    return self.ensure_sync(self.view_functions[rule.endpoint])(**view_args)
           ^^^^^^^^^^^^^^^^^^^^^^^^^^^^^^^^^^^^^^^^^^^^^^^^^^^^^^^^^^^^^^^^^
  File "C:\Users\ashiq\AppData\Local\Programs\Python\Python312\Lib\site-packages\flask_admin\base.py", line 69, in inner
    return self._run_view(f, *args, **kwargs)
           ^^^^^^^^^^^^^^^^^^^^^^^^^^^^^^^^^^
  File "C:\Users\ashiq\AppData\Local\Programs\Python\Python312\Lib\site-packages\flask_admin\base.py", line 369, in _run_view
    return fn(self, *args, **kwargs)
           ^^^^^^^^^^^^^^^^^^^^^^^^^
  File "C:\Users\ashiq\AppData\Local\Programs\Python\Python312\Lib\site-packages\flask_admin\model\base.py", line 2100, in create_view
    model = self.create_model(form)
            ^^^^^^^^^^^^^^^^^^^^^^^
  File "C:\Users\ashiq\AppData\Local\Programs\Python\Python312\Lib\site-packages\flask_admin\contrib\sqla\view.py", line 1165, in create_model
    if not self.handle_view_exception(ex):
           ^^^^^^^^^^^^^^^^^^^^^^^^^^^^^^
  File "C:\Users\ashiq\AppData\Local\Programs\Python\Python312\Lib\site-packages\flask_admin\contrib\sqla\view.py", line 1130, in handle_view_exception
    flash(gettext('Integrity error. %(message)s', message=text_type(exc)), 'error')
  File "C:\Users\ashiq\AppData\Local\Programs\Python\Python312\Lib\site-packages\flask\helpers.py", line 328, in flash
    session["_flashes"] = flashes
    ~~~~~~~^^^^^^^^^^^^
  File "C:\Users\ashiq\AppData\Local\Programs\Python\Python312\Lib\site-packages\flask\sessions.py", line 97, in _fail
    raise RuntimeError(
RuntimeError: The session is unavailable because no secret key was set.  Set the secret_key on the application to something unique and secret.
2025-08-11 10:58:10 - app - ERROR - Exception on /admin/course/new/ [POST]
Traceback (most recent call last):
  File "C:\Users\ashiq\AppData\Local\Programs\Python\Python312\Lib\site-packages\sqlalchemy\engine\base.py", line 1963, in _exec_single_context
    self.dialect.do_execute(
  File "C:\Users\ashiq\AppData\Local\Programs\Python\Python312\Lib\site-packages\sqlalchemy\engine\default.py", line 943, in do_execute
    cursor.execute(statement, parameters)
psycopg2.errors.NotNullViolation: null value in column "syllabus_id" of relation "courses" violates not-null constraint
DETAIL:  Failing row contains (4, ashiq, null, null).


The above exception was the direct cause of the following exception:

Traceback (most recent call last):
  File "C:\Users\ashiq\AppData\Local\Programs\Python\Python312\Lib\site-packages\flask_admin\contrib\sqla\view.py", line 1163, in create_model
    self.session.commit()
  File "C:\Users\ashiq\AppData\Local\Programs\Python\Python312\Lib\site-packages\sqlalchemy\orm\scoping.py", line 599, in commit
    return self._proxied.commit()
           ^^^^^^^^^^^^^^^^^^^^^^
  File "C:\Users\ashiq\AppData\Local\Programs\Python\Python312\Lib\site-packages\sqlalchemy\orm\session.py", line 2032, in commit
    trans.commit(_to_root=True)
  File "<string>", line 2, in commit
  File "C:\Users\ashiq\AppData\Local\Programs\Python\Python312\Lib\site-packages\sqlalchemy\orm\state_changes.py", line 139, in _go
    ret_value = fn(self, *arg, **kw)
                ^^^^^^^^^^^^^^^^^^^^
  File "C:\Users\ashiq\AppData\Local\Programs\Python\Python312\Lib\site-packages\sqlalchemy\orm\session.py", line 1313, in commit
    self._prepare_impl()
  File "<string>", line 2, in _prepare_impl
  File "C:\Users\ashiq\AppData\Local\Programs\Python\Python312\Lib\site-packages\sqlalchemy\orm\state_changes.py", line 139, in _go
    ret_value = fn(self, *arg, **kw)
                ^^^^^^^^^^^^^^^^^^^^
  File "C:\Users\ashiq\AppData\Local\Programs\Python\Python312\Lib\site-packages\sqlalchemy\orm\session.py", line 1288, in _prepare_impl
    self.session.flush()
  File "C:\Users\ashiq\AppData\Local\Programs\Python\Python312\Lib\site-packages\sqlalchemy\orm\session.py", line 4345, in flush
    self._flush(objects)
  File "C:\Users\ashiq\AppData\Local\Programs\Python\Python312\Lib\site-packages\sqlalchemy\orm\session.py", line 4480, in _flush
    with util.safe_reraise():
  File "C:\Users\ashiq\AppData\Local\Programs\Python\Python312\Lib\site-packages\sqlalchemy\util\langhelpers.py", line 224, in __exit__
    raise exc_value.with_traceback(exc_tb)
  File "C:\Users\ashiq\AppData\Local\Programs\Python\Python312\Lib\site-packages\sqlalchemy\orm\session.py", line 4441, in _flush
    flush_context.execute()
  File "C:\Users\ashiq\AppData\Local\Programs\Python\Python312\Lib\site-packages\sqlalchemy\orm\unitofwork.py", line 466, in execute
    rec.execute(self)
  File "C:\Users\ashiq\AppData\Local\Programs\Python\Python312\Lib\site-packages\sqlalchemy\orm\unitofwork.py", line 642, in execute
    util.preloaded.orm_persistence.save_obj(
  File "C:\Users\ashiq\AppData\Local\Programs\Python\Python312\Lib\site-packages\sqlalchemy\orm\persistence.py", line 93, in save_obj
    _emit_insert_statements(
  File "C:\Users\ashiq\AppData\Local\Programs\Python\Python312\Lib\site-packages\sqlalchemy\orm\persistence.py", line 1233, in _emit_insert_statements
    result = connection.execute(
             ^^^^^^^^^^^^^^^^^^^
  File "C:\Users\ashiq\AppData\Local\Programs\Python\Python312\Lib\site-packages\sqlalchemy\engine\base.py", line 1415, in execute
    return meth(
           ^^^^^
  File "C:\Users\ashiq\AppData\Local\Programs\Python\Python312\Lib\site-packages\sqlalchemy\sql\elements.py", line 523, in _execute_on_connection
    return connection._execute_clauseelement(
           ^^^^^^^^^^^^^^^^^^^^^^^^^^^^^^^^^^
  File "C:\Users\ashiq\AppData\Local\Programs\Python\Python312\Lib\site-packages\sqlalchemy\engine\base.py", line 1637, in _execute_clauseelement
    ret = self._execute_context(
          ^^^^^^^^^^^^^^^^^^^^^^
  File "C:\Users\ashiq\AppData\Local\Programs\Python\Python312\Lib\site-packages\sqlalchemy\engine\base.py", line 1842, in _execute_context
    return self._exec_single_context(
           ^^^^^^^^^^^^^^^^^^^^^^^^^^
  File "C:\Users\ashiq\AppData\Local\Programs\Python\Python312\Lib\site-packages\sqlalchemy\engine\base.py", line 1982, in _exec_single_context
    self._handle_dbapi_exception(
  File "C:\Users\ashiq\AppData\Local\Programs\Python\Python312\Lib\site-packages\sqlalchemy\engine\base.py", line 2351, in _handle_dbapi_exception
    raise sqlalchemy_exception.with_traceback(exc_info[2]) from e
  File "C:\Users\ashiq\AppData\Local\Programs\Python\Python312\Lib\site-packages\sqlalchemy\engine\base.py", line 1963, in _exec_single_context
    self.dialect.do_execute(
  File "C:\Users\ashiq\AppData\Local\Programs\Python\Python312\Lib\site-packages\sqlalchemy\engine\default.py", line 943, in do_execute
    cursor.execute(statement, parameters)
sqlalchemy.exc.IntegrityError: (psycopg2.errors.NotNullViolation) null value in column "syllabus_id" of relation "courses" violates not-null constraint
DETAIL:  Failing row contains (4, ashiq, null, null).

[SQL: INSERT INTO courses (name) VALUES (%(name)s) RETURNING courses.id]
[parameters: {'name': 'ashiq'}]
(Background on this error at: https://sqlalche.me/e/20/gkpj)

During handling of the above exception, another exception occurred:

Traceback (most recent call last):
  File "C:\Users\ashiq\AppData\Local\Programs\Python\Python312\Lib\site-packages\flask\app.py", line 2190, in wsgi_app
    response = self.full_dispatch_request()
               ^^^^^^^^^^^^^^^^^^^^^^^^^^^^
  File "C:\Users\ashiq\AppData\Local\Programs\Python\Python312\Lib\site-packages\flask\app.py", line 1486, in full_dispatch_request
    rv = self.handle_user_exception(e)
         ^^^^^^^^^^^^^^^^^^^^^^^^^^^^^
  File "C:\Users\ashiq\AppData\Local\Programs\Python\Python312\Lib\site-packages\flask\app.py", line 1484, in full_dispatch_request
    rv = self.dispatch_request()
         ^^^^^^^^^^^^^^^^^^^^^^^
  File "C:\Users\ashiq\AppData\Local\Programs\Python\Python312\Lib\site-packages\flask\app.py", line 1469, in dispatch_request
    return self.ensure_sync(self.view_functions[rule.endpoint])(**view_args)
           ^^^^^^^^^^^^^^^^^^^^^^^^^^^^^^^^^^^^^^^^^^^^^^^^^^^^^^^^^^^^^^^^^
  File "C:\Users\ashiq\AppData\Local\Programs\Python\Python312\Lib\site-packages\flask_admin\base.py", line 69, in inner
    return self._run_view(f, *args, **kwargs)
           ^^^^^^^^^^^^^^^^^^^^^^^^^^^^^^^^^^
  File "C:\Users\ashiq\AppData\Local\Programs\Python\Python312\Lib\site-packages\flask_admin\base.py", line 369, in _run_view
    return fn(self, *args, **kwargs)
           ^^^^^^^^^^^^^^^^^^^^^^^^^
  File "C:\Users\ashiq\AppData\Local\Programs\Python\Python312\Lib\site-packages\flask_admin\model\base.py", line 2100, in create_view
    model = self.create_model(form)
            ^^^^^^^^^^^^^^^^^^^^^^^
  File "C:\Users\ashiq\AppData\Local\Programs\Python\Python312\Lib\site-packages\flask_admin\contrib\sqla\view.py", line 1165, in create_model
    if not self.handle_view_exception(ex):
           ^^^^^^^^^^^^^^^^^^^^^^^^^^^^^^
  File "C:\Users\ashiq\AppData\Local\Programs\Python\Python312\Lib\site-packages\flask_admin\contrib\sqla\view.py", line 1130, in handle_view_exception
    flash(gettext('Integrity error. %(message)s', message=text_type(exc)), 'error')
  File "C:\Users\ashiq\AppData\Local\Programs\Python\Python312\Lib\site-packages\flask\helpers.py", line 328, in flash
    session["_flashes"] = flashes
    ~~~~~~~^^^^^^^^^^^^
  File "C:\Users\ashiq\AppData\Local\Programs\Python\Python312\Lib\site-packages\flask\sessions.py", line 97, in _fail
    raise RuntimeError(
RuntimeError: The session is unavailable because no secret key was set.  Set the secret_key on the application to something unique and secret.
2025-08-11 11:00:01 - app - ERROR - Exception on /admin/course/new/ [POST]
Traceback (most recent call last):
  File "C:\Users\ashiq\AppData\Local\Programs\Python\Python312\Lib\site-packages\flask\app.py", line 2190, in wsgi_app
    response = self.full_dispatch_request()
               ^^^^^^^^^^^^^^^^^^^^^^^^^^^^
  File "C:\Users\ashiq\AppData\Local\Programs\Python\Python312\Lib\site-packages\flask\app.py", line 1486, in full_dispatch_request
    rv = self.handle_user_exception(e)
         ^^^^^^^^^^^^^^^^^^^^^^^^^^^^^
  File "C:\Users\ashiq\AppData\Local\Programs\Python\Python312\Lib\site-packages\flask\app.py", line 1484, in full_dispatch_request
    rv = self.dispatch_request()
         ^^^^^^^^^^^^^^^^^^^^^^^
  File "C:\Users\ashiq\AppData\Local\Programs\Python\Python312\Lib\site-packages\flask\app.py", line 1469, in dispatch_request
    return self.ensure_sync(self.view_functions[rule.endpoint])(**view_args)
           ^^^^^^^^^^^^^^^^^^^^^^^^^^^^^^^^^^^^^^^^^^^^^^^^^^^^^^^^^^^^^^^^^
  File "C:\Users\ashiq\AppData\Local\Programs\Python\Python312\Lib\site-packages\flask_admin\base.py", line 69, in inner
    return self._run_view(f, *args, **kwargs)
           ^^^^^^^^^^^^^^^^^^^^^^^^^^^^^^^^^^
  File "C:\Users\ashiq\AppData\Local\Programs\Python\Python312\Lib\site-packages\flask_admin\base.py", line 369, in _run_view
    return fn(self, *args, **kwargs)
           ^^^^^^^^^^^^^^^^^^^^^^^^^
  File "C:\Users\ashiq\AppData\Local\Programs\Python\Python312\Lib\site-packages\flask_admin\model\base.py", line 2102, in create_view
    flash(gettext('Record was successfully created.'), 'success')
  File "C:\Users\ashiq\AppData\Local\Programs\Python\Python312\Lib\site-packages\flask\helpers.py", line 328, in flash
    session["_flashes"] = flashes
    ~~~~~~~^^^^^^^^^^^^
  File "C:\Users\ashiq\AppData\Local\Programs\Python\Python312\Lib\site-packages\flask\sessions.py", line 97, in _fail
    raise RuntimeError(
RuntimeError: The session is unavailable because no secret key was set.  Set the secret_key on the application to something unique and secret.
2025-08-11 11:22:20 - app - ERROR - Exception on /admin/syllabus/new/ [POST]
Traceback (most recent call last):
  File "C:\Users\ashiq\AppData\Local\Programs\Python\Python312\Lib\site-packages\flask\app.py", line 2190, in wsgi_app
    response = self.full_dispatch_request()
               ^^^^^^^^^^^^^^^^^^^^^^^^^^^^
  File "C:\Users\ashiq\AppData\Local\Programs\Python\Python312\Lib\site-packages\flask\app.py", line 1486, in full_dispatch_request
    rv = self.handle_user_exception(e)
         ^^^^^^^^^^^^^^^^^^^^^^^^^^^^^
  File "C:\Users\ashiq\AppData\Local\Programs\Python\Python312\Lib\site-packages\flask\app.py", line 1484, in full_dispatch_request
    rv = self.dispatch_request()
         ^^^^^^^^^^^^^^^^^^^^^^^
  File "C:\Users\ashiq\AppData\Local\Programs\Python\Python312\Lib\site-packages\flask\app.py", line 1469, in dispatch_request
    return self.ensure_sync(self.view_functions[rule.endpoint])(**view_args)
           ^^^^^^^^^^^^^^^^^^^^^^^^^^^^^^^^^^^^^^^^^^^^^^^^^^^^^^^^^^^^^^^^^
  File "C:\Users\ashiq\AppData\Local\Programs\Python\Python312\Lib\site-packages\flask_admin\base.py", line 69, in inner
    return self._run_view(f, *args, **kwargs)
           ^^^^^^^^^^^^^^^^^^^^^^^^^^^^^^^^^^
  File "C:\Users\ashiq\AppData\Local\Programs\Python\Python312\Lib\site-packages\flask_admin\base.py", line 369, in _run_view
    return fn(self, *args, **kwargs)
           ^^^^^^^^^^^^^^^^^^^^^^^^^
  File "C:\Users\ashiq\AppData\Local\Programs\Python\Python312\Lib\site-packages\flask_admin\model\base.py", line 2102, in create_view
    flash(gettext('Record was successfully created.'), 'success')
  File "C:\Users\ashiq\AppData\Local\Programs\Python\Python312\Lib\site-packages\flask\helpers.py", line 328, in flash
    session["_flashes"] = flashes
    ~~~~~~~^^^^^^^^^^^^
  File "C:\Users\ashiq\AppData\Local\Programs\Python\Python312\Lib\site-packages\flask\sessions.py", line 97, in _fail
    raise RuntimeError(
RuntimeError: The session is unavailable because no secret key was set.  Set the secret_key on the application to something unique and secret.
2025-08-11 11:26:07 - app - ERROR - Exception on /admin/standard/new/ [POST]
Traceback (most recent call last):
  File "C:\Users\ashiq\AppData\Local\Programs\Python\Python312\Lib\site-packages\flask\app.py", line 2190, in wsgi_app
    response = self.full_dispatch_request()
               ^^^^^^^^^^^^^^^^^^^^^^^^^^^^
  File "C:\Users\ashiq\AppData\Local\Programs\Python\Python312\Lib\site-packages\flask\app.py", line 1486, in full_dispatch_request
    rv = self.handle_user_exception(e)
         ^^^^^^^^^^^^^^^^^^^^^^^^^^^^^
  File "C:\Users\ashiq\AppData\Local\Programs\Python\Python312\Lib\site-packages\flask\app.py", line 1484, in full_dispatch_request
    rv = self.dispatch_request()
         ^^^^^^^^^^^^^^^^^^^^^^^
  File "C:\Users\ashiq\AppData\Local\Programs\Python\Python312\Lib\site-packages\flask\app.py", line 1469, in dispatch_request
    return self.ensure_sync(self.view_functions[rule.endpoint])(**view_args)
           ^^^^^^^^^^^^^^^^^^^^^^^^^^^^^^^^^^^^^^^^^^^^^^^^^^^^^^^^^^^^^^^^^
  File "C:\Users\ashiq\AppData\Local\Programs\Python\Python312\Lib\site-packages\flask_admin\base.py", line 69, in inner
    return self._run_view(f, *args, **kwargs)
           ^^^^^^^^^^^^^^^^^^^^^^^^^^^^^^^^^^
  File "C:\Users\ashiq\AppData\Local\Programs\Python\Python312\Lib\site-packages\flask_admin\base.py", line 369, in _run_view
    return fn(self, *args, **kwargs)
           ^^^^^^^^^^^^^^^^^^^^^^^^^
  File "C:\Users\ashiq\AppData\Local\Programs\Python\Python312\Lib\site-packages\flask_admin\model\base.py", line 2102, in create_view
    flash(gettext('Record was successfully created.'), 'success')
  File "C:\Users\ashiq\AppData\Local\Programs\Python\Python312\Lib\site-packages\flask\helpers.py", line 328, in flash
    session["_flashes"] = flashes
    ~~~~~~~^^^^^^^^^^^^
  File "C:\Users\ashiq\AppData\Local\Programs\Python\Python312\Lib\site-packages\flask\sessions.py", line 97, in _fail
    raise RuntimeError(
RuntimeError: The session is unavailable because no secret key was set.  Set the secret_key on the application to something unique and secret.
2025-08-11 11:39:14 - app - ERROR - Exception on /admin/document/ [GET]
Traceback (most recent call last):
  File "C:\Users\ashiq\AppData\Local\Programs\Python\Python312\Lib\site-packages\sqlalchemy\engine\base.py", line 1963, in _exec_single_context
    self.dialect.do_execute(
  File "C:\Users\ashiq\AppData\Local\Programs\Python\Python312\Lib\site-packages\sqlalchemy\engine\default.py", line 943, in do_execute
    cursor.execute(statement, parameters)
psycopg2.errors.UndefinedColumn: column documents.subject_id does not exist
LINE 2: ...ER JOIN subjects AS subjects_1 ON subjects_1.id = documents....
                                                             ^


The above exception was the direct cause of the following exception:

Traceback (most recent call last):
  File "C:\Users\ashiq\AppData\Local\Programs\Python\Python312\Lib\site-packages\flask\app.py", line 2190, in wsgi_app
    response = self.full_dispatch_request()
               ^^^^^^^^^^^^^^^^^^^^^^^^^^^^
  File "C:\Users\ashiq\AppData\Local\Programs\Python\Python312\Lib\site-packages\flask\app.py", line 1486, in full_dispatch_request
    rv = self.handle_user_exception(e)
         ^^^^^^^^^^^^^^^^^^^^^^^^^^^^^
  File "C:\Users\ashiq\AppData\Local\Programs\Python\Python312\Lib\site-packages\flask\app.py", line 1484, in full_dispatch_request
    rv = self.dispatch_request()
         ^^^^^^^^^^^^^^^^^^^^^^^
  File "C:\Users\ashiq\AppData\Local\Programs\Python\Python312\Lib\site-packages\flask\app.py", line 1469, in dispatch_request
    return self.ensure_sync(self.view_functions[rule.endpoint])(**view_args)
           ^^^^^^^^^^^^^^^^^^^^^^^^^^^^^^^^^^^^^^^^^^^^^^^^^^^^^^^^^^^^^^^^^
  File "C:\Users\ashiq\AppData\Local\Programs\Python\Python312\Lib\site-packages\flask_admin\base.py", line 69, in inner
    return self._run_view(f, *args, **kwargs)
           ^^^^^^^^^^^^^^^^^^^^^^^^^^^^^^^^^^
  File "C:\Users\ashiq\AppData\Local\Programs\Python\Python312\Lib\site-packages\flask_admin\base.py", line 369, in _run_view
    return fn(self, *args, **kwargs)
           ^^^^^^^^^^^^^^^^^^^^^^^^^
  File "C:\Users\ashiq\AppData\Local\Programs\Python\Python312\Lib\site-packages\flask_admin\model\base.py", line 1980, in index_view
    count, data = self.get_list(view_args.page, sort_column, view_args.sort_desc,
                  ^^^^^^^^^^^^^^^^^^^^^^^^^^^^^^^^^^^^^^^^^^^^^^^^^^^^^^^^^^^^^^^
  File "C:\Users\ashiq\AppData\Local\Programs\Python\Python312\Lib\site-packages\flask_admin\contrib\sqla\view.py", line 1100, in get_list
    query = query.all()
            ^^^^^^^^^^^
  File "C:\Users\ashiq\AppData\Local\Programs\Python\Python312\Lib\site-packages\sqlalchemy\orm\query.py", line 2704, in all
    return self._iter().all()  # type: ignore
           ^^^^^^^^^^^^
  File "C:\Users\ashiq\AppData\Local\Programs\Python\Python312\Lib\site-packages\sqlalchemy\orm\query.py", line 2857, in _iter
    result: Union[ScalarResult[_T], Result[_T]] = self.session.execute(
                                                  ^^^^^^^^^^^^^^^^^^^^^
  File "C:\Users\ashiq\AppData\Local\Programs\Python\Python312\Lib\site-packages\sqlalchemy\orm\session.py", line 2365, in execute
    return self._execute_internal(
           ^^^^^^^^^^^^^^^^^^^^^^^
  File "C:\Users\ashiq\AppData\Local\Programs\Python\Python312\Lib\site-packages\sqlalchemy\orm\session.py", line 2251, in _execute_internal
    result: Result[Any] = compile_state_cls.orm_execute_statement(
                          ^^^^^^^^^^^^^^^^^^^^^^^^^^^^^^^^^^^^^^^^
  File "C:\Users\ashiq\AppData\Local\Programs\Python\Python312\Lib\site-packages\sqlalchemy\orm\context.py", line 306, in orm_execute_statement
    result = conn.execute(
             ^^^^^^^^^^^^^
  File "C:\Users\ashiq\AppData\Local\Programs\Python\Python312\Lib\site-packages\sqlalchemy\engine\base.py", line 1415, in execute
    return meth(
           ^^^^^
  File "C:\Users\ashiq\AppData\Local\Programs\Python\Python312\Lib\site-packages\sqlalchemy\sql\elements.py", line 523, in _execute_on_connection
    return connection._execute_clauseelement(
           ^^^^^^^^^^^^^^^^^^^^^^^^^^^^^^^^^^
  File "C:\Users\ashiq\AppData\Local\Programs\Python\Python312\Lib\site-packages\sqlalchemy\engine\base.py", line 1637, in _execute_clauseelement
    ret = self._execute_context(
          ^^^^^^^^^^^^^^^^^^^^^^
  File "C:\Users\ashiq\AppData\Local\Programs\Python\Python312\Lib\site-packages\sqlalchemy\engine\base.py", line 1842, in _execute_context
    return self._exec_single_context(
           ^^^^^^^^^^^^^^^^^^^^^^^^^^
  File "C:\Users\ashiq\AppData\Local\Programs\Python\Python312\Lib\site-packages\sqlalchemy\engine\base.py", line 1982, in _exec_single_context
    self._handle_dbapi_exception(
  File "C:\Users\ashiq\AppData\Local\Programs\Python\Python312\Lib\site-packages\sqlalchemy\engine\base.py", line 2351, in _handle_dbapi_exception
    raise sqlalchemy_exception.with_traceback(exc_info[2]) from e
  File "C:\Users\ashiq\AppData\Local\Programs\Python\Python312\Lib\site-packages\sqlalchemy\engine\base.py", line 1963, in _exec_single_context
    self.dialect.do_execute(
  File "C:\Users\ashiq\AppData\Local\Programs\Python\Python312\Lib\site-packages\sqlalchemy\engine\default.py", line 943, in do_execute
    cursor.execute(statement, parameters)
sqlalchemy.exc.ProgrammingError: (psycopg2.errors.UndefinedColumn) column documents.subject_id does not exist
LINE 2: ...ER JOIN subjects AS subjects_1 ON subjects_1.id = documents....
                                                             ^

[SQL: SELECT documents.id AS documents_id, documents.source_url AS documents_source_url, documents.created_at AS documents_created_at, documents.syllabus_id AS documents_syllabus_id, documents.class_id AS documents_class_id, documents.subject_id AS documents_subject_id, syllabuses_1.id AS syllabuses_1_id, syllabuses_1.name AS syllabuses_1_name, classes_1.id AS classes_1_id, classes_1.name AS classes_1_name, subjects_1.id AS subjects_1_id, subjects_1.name AS subjects_1_name 
FROM documents LEFT OUTER JOIN syllabuses AS syllabuses_1 ON syllabuses_1.id = documents.syllabus_id LEFT OUTER JOIN classes AS classes_1 ON classes_1.id = documents.class_id LEFT OUTER JOIN subjects AS subjects_1 ON subjects_1.id = documents.subject_id 
 LIMIT %(param_1)s]
[parameters: {'param_1': 20}]
(Background on this error at: https://sqlalche.me/e/20/f405)
2025-08-11 11:48:16 - app - INFO - Document created: 11c2ab92-b7fb-42a3-b6ef-a6ffb86d905d. Triggering embedding process.
2025-08-11 11:48:16 - app - INFO - Starting embedding process for Document ID: 11c2ab92-b7fb-42a3-b6ef-a6ffb86d905d
2025-08-11 11:48:21 - app - INFO - Successfully processed and embedded Document ID: 11c2ab92-b7fb-42a3-b6ef-a6ffb86d905d
2025-08-11 11:52:27 - app - ERROR - Exception on /admin/document/ [GET]
Traceback (most recent call last):
  File "C:\Users\ashiq\AppData\Local\Programs\Python\Python312\Lib\site-packages\sqlalchemy\engine\base.py", line 1963, in _exec_single_context
    self.dialect.do_execute(
  File "C:\Users\ashiq\AppData\Local\Programs\Python\Python312\Lib\site-packages\sqlalchemy\engine\default.py", line 943, in do_execute
    cursor.execute(statement, parameters)
psycopg2.errors.UndefinedColumn: column documents.processing_status does not exist
LINE 1: ...rl, documents.created_at AS documents_created_at, documents....
                                                             ^


The above exception was the direct cause of the following exception:

Traceback (most recent call last):
  File "C:\Users\ashiq\AppData\Local\Programs\Python\Python312\Lib\site-packages\flask\app.py", line 2190, in wsgi_app
    response = self.full_dispatch_request()
               ^^^^^^^^^^^^^^^^^^^^^^^^^^^^
  File "C:\Users\ashiq\AppData\Local\Programs\Python\Python312\Lib\site-packages\flask\app.py", line 1486, in full_dispatch_request
    rv = self.handle_user_exception(e)
         ^^^^^^^^^^^^^^^^^^^^^^^^^^^^^
  File "C:\Users\ashiq\AppData\Local\Programs\Python\Python312\Lib\site-packages\flask\app.py", line 1484, in full_dispatch_request
    rv = self.dispatch_request()
         ^^^^^^^^^^^^^^^^^^^^^^^
  File "C:\Users\ashiq\AppData\Local\Programs\Python\Python312\Lib\site-packages\flask\app.py", line 1469, in dispatch_request
    return self.ensure_sync(self.view_functions[rule.endpoint])(**view_args)
           ^^^^^^^^^^^^^^^^^^^^^^^^^^^^^^^^^^^^^^^^^^^^^^^^^^^^^^^^^^^^^^^^^
  File "C:\Users\ashiq\AppData\Local\Programs\Python\Python312\Lib\site-packages\flask_admin\base.py", line 69, in inner
    return self._run_view(f, *args, **kwargs)
           ^^^^^^^^^^^^^^^^^^^^^^^^^^^^^^^^^^
  File "C:\Users\ashiq\AppData\Local\Programs\Python\Python312\Lib\site-packages\flask_admin\base.py", line 369, in _run_view
    return fn(self, *args, **kwargs)
           ^^^^^^^^^^^^^^^^^^^^^^^^^
  File "C:\Users\ashiq\AppData\Local\Programs\Python\Python312\Lib\site-packages\flask_admin\model\base.py", line 1980, in index_view
    count, data = self.get_list(view_args.page, sort_column, view_args.sort_desc,
                  ^^^^^^^^^^^^^^^^^^^^^^^^^^^^^^^^^^^^^^^^^^^^^^^^^^^^^^^^^^^^^^^
  File "C:\Users\ashiq\AppData\Local\Programs\Python\Python312\Lib\site-packages\flask_admin\contrib\sqla\view.py", line 1100, in get_list
    query = query.all()
            ^^^^^^^^^^^
  File "C:\Users\ashiq\AppData\Local\Programs\Python\Python312\Lib\site-packages\sqlalchemy\orm\query.py", line 2704, in all
    return self._iter().all()  # type: ignore
           ^^^^^^^^^^^^
  File "C:\Users\ashiq\AppData\Local\Programs\Python\Python312\Lib\site-packages\sqlalchemy\orm\query.py", line 2857, in _iter
    result: Union[ScalarResult[_T], Result[_T]] = self.session.execute(
                                                  ^^^^^^^^^^^^^^^^^^^^^
  File "C:\Users\ashiq\AppData\Local\Programs\Python\Python312\Lib\site-packages\sqlalchemy\orm\session.py", line 2365, in execute
    return self._execute_internal(
           ^^^^^^^^^^^^^^^^^^^^^^^
  File "C:\Users\ashiq\AppData\Local\Programs\Python\Python312\Lib\site-packages\sqlalchemy\orm\session.py", line 2251, in _execute_internal
    result: Result[Any] = compile_state_cls.orm_execute_statement(
                          ^^^^^^^^^^^^^^^^^^^^^^^^^^^^^^^^^^^^^^^^
  File "C:\Users\ashiq\AppData\Local\Programs\Python\Python312\Lib\site-packages\sqlalchemy\orm\context.py", line 306, in orm_execute_statement
    result = conn.execute(
             ^^^^^^^^^^^^^
  File "C:\Users\ashiq\AppData\Local\Programs\Python\Python312\Lib\site-packages\sqlalchemy\engine\base.py", line 1415, in execute
    return meth(
           ^^^^^
  File "C:\Users\ashiq\AppData\Local\Programs\Python\Python312\Lib\site-packages\sqlalchemy\sql\elements.py", line 523, in _execute_on_connection
    return connection._execute_clauseelement(
           ^^^^^^^^^^^^^^^^^^^^^^^^^^^^^^^^^^
  File "C:\Users\ashiq\AppData\Local\Programs\Python\Python312\Lib\site-packages\sqlalchemy\engine\base.py", line 1637, in _execute_clauseelement
    ret = self._execute_context(
          ^^^^^^^^^^^^^^^^^^^^^^
  File "C:\Users\ashiq\AppData\Local\Programs\Python\Python312\Lib\site-packages\sqlalchemy\engine\base.py", line 1842, in _execute_context
    return self._exec_single_context(
           ^^^^^^^^^^^^^^^^^^^^^^^^^^
  File "C:\Users\ashiq\AppData\Local\Programs\Python\Python312\Lib\site-packages\sqlalchemy\engine\base.py", line 1982, in _exec_single_context
    self._handle_dbapi_exception(
  File "C:\Users\ashiq\AppData\Local\Programs\Python\Python312\Lib\site-packages\sqlalchemy\engine\base.py", line 2351, in _handle_dbapi_exception
    raise sqlalchemy_exception.with_traceback(exc_info[2]) from e
  File "C:\Users\ashiq\AppData\Local\Programs\Python\Python312\Lib\site-packages\sqlalchemy\engine\base.py", line 1963, in _exec_single_context
    self.dialect.do_execute(
  File "C:\Users\ashiq\AppData\Local\Programs\Python\Python312\Lib\site-packages\sqlalchemy\engine\default.py", line 943, in do_execute
    cursor.execute(statement, parameters)
sqlalchemy.exc.ProgrammingError: (psycopg2.errors.UndefinedColumn) column documents.processing_status does not exist
LINE 1: ...rl, documents.created_at AS documents_created_at, documents....
                                                             ^

[SQL: SELECT documents.id AS documents_id, documents.source_url AS documents_source_url, documents.created_at AS documents_created_at, documents.processing_status AS documents_processing_status, documents.processing_time_ms AS documents_processing_time_ms, documents.syllabus_id AS documents_syllabus_id, documents.class_id AS documents_class_id, documents.subject_id AS documents_subject_id, subjects_1.id AS subjects_1_id, subjects_1.name AS subjects_1_name 
FROM documents LEFT OUTER JOIN subjects AS subjects_1 ON subjects_1.id = documents.subject_id 
 LIMIT %(param_1)s]
[parameters: {'param_1': 20}]
(Background on this error at: https://sqlalche.me/e/20/f405)
2025-08-11 12:00:30 - app - INFO - Document created: ee3c2221-9741-4b81-989c-557243acc212. Triggering embedding process.
2025-08-11 12:00:30 - app - INFO - Set status to PROCESSING for Document ID: ee3c2221-9741-4b81-989c-557243acc212
2025-08-11 12:00:35 - app - INFO - Successfully processed. Status set to COMPLETED for Document ID: ee3c2221-9741-4b81-989c-557243acc212
2025-08-11 12:02:10 - app - ERROR - Exception on /api/login [POST]
Traceback (most recent call last):
  File "C:\Users\ashiq\AppData\Local\Programs\Python\Python312\Lib\site-packages\flask\app.py", line 2190, in wsgi_app
    response = self.full_dispatch_request()
               ^^^^^^^^^^^^^^^^^^^^^^^^^^^^
  File "C:\Users\ashiq\AppData\Local\Programs\Python\Python312\Lib\site-packages\flask\app.py", line 1486, in full_dispatch_request
    rv = self.handle_user_exception(e)
         ^^^^^^^^^^^^^^^^^^^^^^^^^^^^^
  File "C:\Users\ashiq\AppData\Local\Programs\Python\Python312\Lib\site-packages\flask\app.py", line 1484, in full_dispatch_request
    rv = self.dispatch_request()
         ^^^^^^^^^^^^^^^^^^^^^^^
  File "C:\Users\ashiq\AppData\Local\Programs\Python\Python312\Lib\site-packages\flask\app.py", line 1469, in dispatch_request
    return self.ensure_sync(self.view_functions[rule.endpoint])(**view_args)
           ^^^^^^^^^^^^^^^^^^^^^^^^^^^^^^^^^^^^^^^^^^^^^^^^^^^^^^^^^^^^^^^^^
  File "C:\Users\ashiq\AppData\Local\Programs\Python\Python312\Lib\site-packages\flask_limiter\extension.py", line 1314, in __inner
    return cast(R, flask.current_app.ensure_sync(obj)(*a, **k))
                   ^^^^^^^^^^^^^^^^^^^^^^^^^^^^^^^^^^^^^^^^^^^
  File "D:\Meshilogic\Syllabus_QA_Chatbot\Syllabus_QA_Chatbot\app\routes.py", line 48, in login
    data = UserLogin_schema().load(request.get_json())
           ^^^^^^^^^^^^^^^^
NameError: name 'UserLogin_schema' is not defined. Did you mean: 'UserLoginSchema'?
2025-08-11 12:02:18 - app - ERROR - Exception on /api/login [POST]
Traceback (most recent call last):
  File "C:\Users\ashiq\AppData\Local\Programs\Python\Python312\Lib\site-packages\flask\app.py", line 2190, in wsgi_app
    response = self.full_dispatch_request()
               ^^^^^^^^^^^^^^^^^^^^^^^^^^^^
  File "C:\Users\ashiq\AppData\Local\Programs\Python\Python312\Lib\site-packages\flask\app.py", line 1486, in full_dispatch_request
    rv = self.handle_user_exception(e)
         ^^^^^^^^^^^^^^^^^^^^^^^^^^^^^
  File "C:\Users\ashiq\AppData\Local\Programs\Python\Python312\Lib\site-packages\flask\app.py", line 1484, in full_dispatch_request
    rv = self.dispatch_request()
         ^^^^^^^^^^^^^^^^^^^^^^^
  File "C:\Users\ashiq\AppData\Local\Programs\Python\Python312\Lib\site-packages\flask\app.py", line 1469, in dispatch_request
    return self.ensure_sync(self.view_functions[rule.endpoint])(**view_args)
           ^^^^^^^^^^^^^^^^^^^^^^^^^^^^^^^^^^^^^^^^^^^^^^^^^^^^^^^^^^^^^^^^^
  File "C:\Users\ashiq\AppData\Local\Programs\Python\Python312\Lib\site-packages\flask_limiter\extension.py", line 1314, in __inner
    return cast(R, flask.current_app.ensure_sync(obj)(*a, **k))
                   ^^^^^^^^^^^^^^^^^^^^^^^^^^^^^^^^^^^^^^^^^^^
  File "D:\Meshilogic\Syllabus_QA_Chatbot\Syllabus_QA_Chatbot\app\routes.py", line 48, in login
    data = UserLogin_schema().load(request.get_json())
           ^^^^^^^^^^^^^^^^
NameError: name 'UserLogin_schema' is not defined. Did you mean: 'UserLoginSchema'?
2025-08-11 12:02:20 - app - ERROR - Exception on /api/login [POST]
Traceback (most recent call last):
  File "C:\Users\ashiq\AppData\Local\Programs\Python\Python312\Lib\site-packages\flask\app.py", line 2190, in wsgi_app
    response = self.full_dispatch_request()
               ^^^^^^^^^^^^^^^^^^^^^^^^^^^^
  File "C:\Users\ashiq\AppData\Local\Programs\Python\Python312\Lib\site-packages\flask\app.py", line 1486, in full_dispatch_request
    rv = self.handle_user_exception(e)
         ^^^^^^^^^^^^^^^^^^^^^^^^^^^^^
  File "C:\Users\ashiq\AppData\Local\Programs\Python\Python312\Lib\site-packages\flask\app.py", line 1484, in full_dispatch_request
    rv = self.dispatch_request()
         ^^^^^^^^^^^^^^^^^^^^^^^
  File "C:\Users\ashiq\AppData\Local\Programs\Python\Python312\Lib\site-packages\flask\app.py", line 1469, in dispatch_request
    return self.ensure_sync(self.view_functions[rule.endpoint])(**view_args)
           ^^^^^^^^^^^^^^^^^^^^^^^^^^^^^^^^^^^^^^^^^^^^^^^^^^^^^^^^^^^^^^^^^
  File "C:\Users\ashiq\AppData\Local\Programs\Python\Python312\Lib\site-packages\flask_limiter\extension.py", line 1314, in __inner
    return cast(R, flask.current_app.ensure_sync(obj)(*a, **k))
                   ^^^^^^^^^^^^^^^^^^^^^^^^^^^^^^^^^^^^^^^^^^^
  File "D:\Meshilogic\Syllabus_QA_Chatbot\Syllabus_QA_Chatbot\app\routes.py", line 48, in login
    data = UserLogin_schema().load(request.get_json())
           ^^^^^^^^^^^^^^^^
NameError: name 'UserLogin_schema' is not defined. Did you mean: 'UserLoginSchema'?
2025-08-11 12:03:14 - app - ERROR - Exception on /api/login [POST]
Traceback (most recent call last):
  File "C:\Users\ashiq\AppData\Local\Programs\Python\Python312\Lib\site-packages\flask\app.py", line 2190, in wsgi_app
    response = self.full_dispatch_request()
               ^^^^^^^^^^^^^^^^^^^^^^^^^^^^
  File "C:\Users\ashiq\AppData\Local\Programs\Python\Python312\Lib\site-packages\flask\app.py", line 1486, in full_dispatch_request
    rv = self.handle_user_exception(e)
         ^^^^^^^^^^^^^^^^^^^^^^^^^^^^^
  File "C:\Users\ashiq\AppData\Local\Programs\Python\Python312\Lib\site-packages\flask\app.py", line 1484, in full_dispatch_request
    rv = self.dispatch_request()
         ^^^^^^^^^^^^^^^^^^^^^^^
  File "C:\Users\ashiq\AppData\Local\Programs\Python\Python312\Lib\site-packages\flask\app.py", line 1469, in dispatch_request
    return self.ensure_sync(self.view_functions[rule.endpoint])(**view_args)
           ^^^^^^^^^^^^^^^^^^^^^^^^^^^^^^^^^^^^^^^^^^^^^^^^^^^^^^^^^^^^^^^^^
  File "C:\Users\ashiq\AppData\Local\Programs\Python\Python312\Lib\site-packages\flask_limiter\extension.py", line 1314, in __inner
    return cast(R, flask.current_app.ensure_sync(obj)(*a, **k))
                   ^^^^^^^^^^^^^^^^^^^^^^^^^^^^^^^^^^^^^^^^^^^
  File "D:\Meshilogic\Syllabus_QA_Chatbot\Syllabus_QA_Chatbot\app\routes.py", line 48, in login
    data = UserLoginSchema().load(request.get_json())
           ^^^^^^^^^^^^^^^^
NameError: name 'UserLogin_schema' is not defined. Did you mean: 'UserLoginSchema'?
2025-08-11 12:03:17 - app - ERROR - Exception on /api/login [POST]
Traceback (most recent call last):
  File "C:\Users\ashiq\AppData\Local\Programs\Python\Python312\Lib\site-packages\flask\app.py", line 2190, in wsgi_app
    response = self.full_dispatch_request()
               ^^^^^^^^^^^^^^^^^^^^^^^^^^^^
  File "C:\Users\ashiq\AppData\Local\Programs\Python\Python312\Lib\site-packages\flask\app.py", line 1486, in full_dispatch_request
    rv = self.handle_user_exception(e)
         ^^^^^^^^^^^^^^^^^^^^^^^^^^^^^
  File "C:\Users\ashiq\AppData\Local\Programs\Python\Python312\Lib\site-packages\flask\app.py", line 1484, in full_dispatch_request
    rv = self.dispatch_request()
         ^^^^^^^^^^^^^^^^^^^^^^^
  File "C:\Users\ashiq\AppData\Local\Programs\Python\Python312\Lib\site-packages\flask\app.py", line 1469, in dispatch_request
    return self.ensure_sync(self.view_functions[rule.endpoint])(**view_args)
           ^^^^^^^^^^^^^^^^^^^^^^^^^^^^^^^^^^^^^^^^^^^^^^^^^^^^^^^^^^^^^^^^^
  File "C:\Users\ashiq\AppData\Local\Programs\Python\Python312\Lib\site-packages\flask_limiter\extension.py", line 1314, in __inner
    return cast(R, flask.current_app.ensure_sync(obj)(*a, **k))
                   ^^^^^^^^^^^^^^^^^^^^^^^^^^^^^^^^^^^^^^^^^^^
  File "D:\Meshilogic\Syllabus_QA_Chatbot\Syllabus_QA_Chatbot\app\routes.py", line 48, in login
    data = UserLoginSchema().load(request.get_json())
           ^^^^^^^^^^^^^^^^
NameError: name 'UserLogin_schema' is not defined. Did you mean: 'UserLoginSchema'?
2025-08-11 12:48:20 - app - ERROR - Exception on /admin/ [GET]
Traceback (most recent call last):
  File "C:\Users\ashiq\AppData\Local\Programs\Python\Python312\Lib\site-packages\flask\app.py", line 2190, in wsgi_app
    response = self.full_dispatch_request()
               ^^^^^^^^^^^^^^^^^^^^^^^^^^^^
  File "C:\Users\ashiq\AppData\Local\Programs\Python\Python312\Lib\site-packages\flask\app.py", line 1486, in full_dispatch_request
    rv = self.handle_user_exception(e)
         ^^^^^^^^^^^^^^^^^^^^^^^^^^^^^
  File "C:\Users\ashiq\AppData\Local\Programs\Python\Python312\Lib\site-packages\flask\app.py", line 1484, in full_dispatch_request
    rv = self.dispatch_request()
         ^^^^^^^^^^^^^^^^^^^^^^^
  File "C:\Users\ashiq\AppData\Local\Programs\Python\Python312\Lib\site-packages\flask\app.py", line 1469, in dispatch_request
    return self.ensure_sync(self.view_functions[rule.endpoint])(**view_args)
           ^^^^^^^^^^^^^^^^^^^^^^^^^^^^^^^^^^^^^^^^^^^^^^^^^^^^^^^^^^^^^^^^^
  File "C:\Users\ashiq\AppData\Local\Programs\Python\Python312\Lib\site-packages\flask_admin\base.py", line 65, in inner
    abort = self._handle_view(f.__name__, **kwargs)
            ^^^^^^^^^^^^^^^^^^^^^^^^^^^^^^^^^^^^^^^
  File "C:\Users\ashiq\AppData\Local\Programs\Python\Python312\Lib\site-packages\flask_admin\base.py", line 353, in _handle_view
    if not self.is_accessible():
           ^^^^^^^^^^^^^^^^^^^^
  File "D:\Meshilogic\Syllabus_QA_Chatbot\Syllabus_QA_Chatbot\app\admin.py", line 93, in is_accessible
    auth.username == current_app.config['ADMIN_USERNAME'] and
                     ~~~~~~~~~~~~~~~~~~^^^^^^^^^^^^^^^^^^
KeyError: 'ADMIN_USERNAME'
2025-08-11 12:49:16 - app - ERROR - Exception on /admin/ [GET]
Traceback (most recent call last):
  File "C:\Users\ashiq\AppData\Local\Programs\Python\Python312\Lib\site-packages\flask\app.py", line 2190, in wsgi_app
    response = self.full_dispatch_request()
               ^^^^^^^^^^^^^^^^^^^^^^^^^^^^
  File "C:\Users\ashiq\AppData\Local\Programs\Python\Python312\Lib\site-packages\flask\app.py", line 1486, in full_dispatch_request
    rv = self.handle_user_exception(e)
         ^^^^^^^^^^^^^^^^^^^^^^^^^^^^^
  File "C:\Users\ashiq\AppData\Local\Programs\Python\Python312\Lib\site-packages\flask\app.py", line 1484, in full_dispatch_request
    rv = self.dispatch_request()
         ^^^^^^^^^^^^^^^^^^^^^^^
  File "C:\Users\ashiq\AppData\Local\Programs\Python\Python312\Lib\site-packages\flask\app.py", line 1469, in dispatch_request
    return self.ensure_sync(self.view_functions[rule.endpoint])(**view_args)
           ^^^^^^^^^^^^^^^^^^^^^^^^^^^^^^^^^^^^^^^^^^^^^^^^^^^^^^^^^^^^^^^^^
  File "C:\Users\ashiq\AppData\Local\Programs\Python\Python312\Lib\site-packages\flask_admin\base.py", line 65, in inner
    abort = self._handle_view(f.__name__, **kwargs)
            ^^^^^^^^^^^^^^^^^^^^^^^^^^^^^^^^^^^^^^^
  File "C:\Users\ashiq\AppData\Local\Programs\Python\Python312\Lib\site-packages\flask_admin\base.py", line 353, in _handle_view
    if not self.is_accessible():
           ^^^^^^^^^^^^^^^^^^^^
  File "D:\Meshilogic\Syllabus_QA_Chatbot\Syllabus_QA_Chatbot\app\admin.py", line 93, in is_accessible
    auth.username == current_app.config['ADMIN_USERNAME'] and
                     ~~~~~~~~~~~~~~~~~~^^^^^^^^^^^^^^^^^^
KeyError: 'ADMIN_USERNAME'
2025-08-11 16:03:04 - app - INFO - Document created: 9e96fa42-15e3-4f40-a15e-26859ae3e86b. Triggering embedding process.
2025-08-11 16:03:04 - app - INFO - Set status to PROCESSING for Document ID: 9e96fa42-15e3-4f40-a15e-26859ae3e86b
2025-08-11 16:03:09 - app - INFO - Successfully processed. Status set to COMPLETED for Document ID: 9e96fa42-15e3-4f40-a15e-26859ae3e86b
2025-08-11 16:12:43 - app - INFO - Document created: 88fa6159-bb94-4370-9938-447284835fe1. Triggering embedding process.
2025-08-11 16:12:43 - app - INFO - Set status to PROCESSING for Document ID: 88fa6159-bb94-4370-9938-447284835fe1
2025-08-11 16:14:13 - app - INFO - Successfully processed. Status set to COMPLETED for Document ID: 88fa6159-bb94-4370-9938-447284835fe1
2025-08-11 20:29:39 - app - INFO - Document created: 323a1a64-b907-4f2d-ab7a-5a09f411805a. Triggering embedding process.
2025-08-11 20:29:39 - app - INFO - Set status to PROCESSING for Document ID: 323a1a64-b907-4f2d-ab7a-5a09f411805a
2025-08-11 20:29:46 - app - INFO - Successfully processed. Status set to COMPLETED for Document ID: 323a1a64-b907-4f2d-ab7a-5a09f411805a
2025-08-11 20:32:12 - app - INFO - Document created: c5764a1d-25e0-4e4f-ab71-b87721894f36. Triggering embedding process.
2025-08-11 20:32:12 - app - INFO - Set status to PROCESSING for Document ID: c5764a1d-25e0-4e4f-ab71-b87721894f36
2025-08-11 20:33:33 - app - INFO - Successfully processed. Status set to COMPLETED for Document ID: c5764a1d-25e0-4e4f-ab71-b87721894f36
2025-08-11 20:39:40 - app - INFO - Document created: eabbf5fb-5644-4908-9a84-7ca68bd80f7d. Triggering embedding process.
2025-08-11 20:39:40 - app - INFO - Set status to PROCESSING for Document ID: eabbf5fb-5644-4908-9a84-7ca68bd80f7d
2025-08-11 20:39:50 - app - INFO - Successfully processed. Status set to COMPLETED for Document ID: eabbf5fb-5644-4908-9a84-7ca68bd80f7d
2025-08-11 20:48:29 - app - INFO - Document created: 70117a22-97ce-48f8-9657-35e3ac7197f6. Triggering embedding process.
2025-08-11 20:48:29 - app - INFO - Set status to PROCESSING for Document ID: 70117a22-97ce-48f8-9657-35e3ac7197f6
2025-08-11 20:49:06 - app - INFO - Successfully processed. Status set to COMPLETED for Document ID: 70117a22-97ce-48f8-9657-35e3ac7197f6
2025-08-12 10:55:40 - app - INFO - Document created: 4cdb8c32-69eb-4b33-b5b4-8495d7d34423. Triggering embedding process.
2025-08-12 10:55:40 - app - INFO - Set status to PROCESSING for Document ID: 4cdb8c32-69eb-4b33-b5b4-8495d7d34423
2025-08-12 10:55:43 - app - INFO - Successfully processed. Status set to COMPLETED for Document ID: 4cdb8c32-69eb-4b33-b5b4-8495d7d34423
2025-08-12 11:15:05 - app - INFO - Source URL changed for Document ID: 70117a22-97ce-48f8-9657-35e3ac7197f6. Deleting old chunks.
2025-08-12 11:15:05 - app - INFO - Triggering embedding process for Document ID: 70117a22-97ce-48f8-9657-35e3ac7197f6.
2025-08-12 11:15:05 - app - INFO - Set status to PROCESSING for Document ID: 70117a22-97ce-48f8-9657-35e3ac7197f6
2025-08-12 11:15:10 - app - INFO - Successfully processed. Status set to COMPLETED for Document ID: 70117a22-97ce-48f8-9657-35e3ac7197f6
2025-08-12 11:18:45 - app - ERROR - Exception on /admin/ [GET]
Traceback (most recent call last):
  File "C:\Users\ashiq\AppData\Local\Programs\Python\Python312\Lib\site-packages\flask\app.py", line 2190, in wsgi_app
    response = self.full_dispatch_request()
               ^^^^^^^^^^^^^^^^^^^^^^^^^^^^
  File "C:\Users\ashiq\AppData\Local\Programs\Python\Python312\Lib\site-packages\flask\app.py", line 1486, in full_dispatch_request
    rv = self.handle_user_exception(e)
         ^^^^^^^^^^^^^^^^^^^^^^^^^^^^^
  File "C:\Users\ashiq\AppData\Local\Programs\Python\Python312\Lib\site-packages\flask_cors\extension.py", line 176, in wrapped_function
    return cors_after_request(app.make_response(f(*args, **kwargs)))
                                                ^^^^^^^^^^^^^^^^^^
  File "C:\Users\ashiq\AppData\Local\Programs\Python\Python312\Lib\site-packages\flask\app.py", line 1484, in full_dispatch_request
    rv = self.dispatch_request()
         ^^^^^^^^^^^^^^^^^^^^^^^
  File "C:\Users\ashiq\AppData\Local\Programs\Python\Python312\Lib\site-packages\flask\app.py", line 1469, in dispatch_request
    return self.ensure_sync(self.view_functions[rule.endpoint])(**view_args)
           ^^^^^^^^^^^^^^^^^^^^^^^^^^^^^^^^^^^^^^^^^^^^^^^^^^^^^^^^^^^^^^^^^
  File "C:\Users\ashiq\AppData\Local\Programs\Python\Python312\Lib\site-packages\flask_admin\base.py", line 69, in inner
    return self._run_view(f, *args, **kwargs)
           ^^^^^^^^^^^^^^^^^^^^^^^^^^^^^^^^^^
  File "C:\Users\ashiq\AppData\Local\Programs\Python\Python312\Lib\site-packages\flask_admin\base.py", line 369, in _run_view
    return fn(self, *args, **kwargs)
           ^^^^^^^^^^^^^^^^^^^^^^^^^
  File "C:\Users\ashiq\AppData\Local\Programs\Python\Python312\Lib\site-packages\flask_admin\base.py", line 455, in index
    return self.render(self._template)
           ^^^^^^^^^^^^^^^^^^^^^^^^^^^
  File "C:\Users\ashiq\AppData\Local\Programs\Python\Python312\Lib\site-packages\flask_admin\base.py", line 308, in render
    return render_template(template, **kwargs)
           ^^^^^^^^^^^^^^^^^^^^^^^^^^^^^^^^^^^
  File "C:\Users\ashiq\AppData\Local\Programs\Python\Python312\Lib\site-packages\flask\templating.py", line 151, in render_template
    return _render(app, template, context)
           ^^^^^^^^^^^^^^^^^^^^^^^^^^^^^^^
  File "C:\Users\ashiq\AppData\Local\Programs\Python\Python312\Lib\site-packages\flask\templating.py", line 132, in _render
    rv = template.render(context)
         ^^^^^^^^^^^^^^^^^^^^^^^^
  File "C:\Users\ashiq\AppData\Local\Programs\Python\Python312\Lib\site-packages\jinja2\environment.py", line 1304, in render
    self.environment.handle_exception()
  File "C:\Users\ashiq\AppData\Local\Programs\Python\Python312\Lib\site-packages\jinja2\environment.py", line 939, in handle_exception
    raise rewrite_traceback_stack(source=source)
  File "C:\Users\ashiq\AppData\Local\Programs\Python\Python312\Lib\site-packages\flask_admin\templates\bootstrap3\admin\index.html", line 1, in top-level template code
    {% extends 'admin/master.html' %}
    ^^^^^^^^^^^^^^^^^^^^^^^^^
  File "C:\Users\ashiq\AppData\Local\Programs\Python\Python312\Lib\site-packages\flask_admin\templates\bootstrap3\admin\master.html", line 1, in top-level template code
    {% extends admin_base_template %}
    ^^^^^^^^^^^^^^^^^^^^^^^^^
  File "C:\Users\ashiq\AppData\Local\Programs\Python\Python312\Lib\site-packages\flask\templating.py", line 64, in get_source
    return self._get_source_fast(environment, template)
           ^^^^^^^^^^^^^^^^^^^^^^^^^^^^^^^^^^^^^^^^^^^^
  File "C:\Users\ashiq\AppData\Local\Programs\Python\Python312\Lib\site-packages\flask\templating.py", line 98, in _get_source_fast
    raise TemplateNotFound(template)
jinja2.exceptions.TemplateNotFound: admin/custom_base.html
2025-08-12 11:23:02 - app - ERROR - Exception on /admin/ [GET]
Traceback (most recent call last):
  File "C:\Users\ashiq\AppData\Local\Programs\Python\Python312\Lib\site-packages\flask\app.py", line 2190, in wsgi_app
    response = self.full_dispatch_request()
               ^^^^^^^^^^^^^^^^^^^^^^^^^^^^
  File "C:\Users\ashiq\AppData\Local\Programs\Python\Python312\Lib\site-packages\flask\app.py", line 1486, in full_dispatch_request
    rv = self.handle_user_exception(e)
         ^^^^^^^^^^^^^^^^^^^^^^^^^^^^^
  File "C:\Users\ashiq\AppData\Local\Programs\Python\Python312\Lib\site-packages\flask_cors\extension.py", line 176, in wrapped_function
    return cors_after_request(app.make_response(f(*args, **kwargs)))
                                                ^^^^^^^^^^^^^^^^^^
  File "C:\Users\ashiq\AppData\Local\Programs\Python\Python312\Lib\site-packages\flask\app.py", line 1484, in full_dispatch_request
    rv = self.dispatch_request()
         ^^^^^^^^^^^^^^^^^^^^^^^
  File "C:\Users\ashiq\AppData\Local\Programs\Python\Python312\Lib\site-packages\flask\app.py", line 1469, in dispatch_request
    return self.ensure_sync(self.view_functions[rule.endpoint])(**view_args)
           ^^^^^^^^^^^^^^^^^^^^^^^^^^^^^^^^^^^^^^^^^^^^^^^^^^^^^^^^^^^^^^^^^
  File "C:\Users\ashiq\AppData\Local\Programs\Python\Python312\Lib\site-packages\flask_admin\base.py", line 65, in inner
    abort = self._handle_view(f.__name__, **kwargs)
            ^^^^^^^^^^^^^^^^^^^^^^^^^^^^^^^^^^^^^^^
  File "C:\Users\ashiq\AppData\Local\Programs\Python\Python312\Lib\site-packages\flask_admin\base.py", line 353, in _handle_view
    if not self.is_accessible():
           ^^^^^^^^^^^^^^^^^^^^
  File "D:\Meshilogic\Syllabus_QA_Chatbot\Syllabus_QA_Chatbot\app\admin.py", line 96, in is_accessible
    return current_user.is_authenticated and current_user.is_admin
           ^^^^^^^^^^^^^^^^^^^^^^^^^^^^^
  File "C:\Users\ashiq\AppData\Local\Programs\Python\Python312\Lib\site-packages\werkzeug\local.py", line 311, in __get__
    obj = instance._get_current_object()
          ^^^^^^^^^^^^^^^^^^^^^^^^^^^^^^
  File "C:\Users\ashiq\AppData\Local\Programs\Python\Python312\Lib\site-packages\werkzeug\local.py", line 515, in _get_current_object
    return get_name(local())
                    ^^^^^^^
  File "C:\Users\ashiq\AppData\Local\Programs\Python\Python312\Lib\site-packages\flask_login\utils.py", line 25, in <lambda>
    current_user = LocalProxy(lambda: _get_user())
                                      ^^^^^^^^^^^
  File "C:\Users\ashiq\AppData\Local\Programs\Python\Python312\Lib\site-packages\flask_login\utils.py", line 372, in _get_user
    current_app.login_manager._load_user()
    ^^^^^^^^^^^^^^^^^^^^^^^^^
AttributeError: 'Flask' object has no attribute 'login_manager'
2025-08-12 11:30:06 - app - INFO - Source URL changed for Document ID: 70117a22-97ce-48f8-9657-35e3ac7197f6. Deleting old chunks.
2025-08-12 11:30:06 - app - INFO - Triggering embedding process for Document ID: 70117a22-97ce-48f8-9657-35e3ac7197f6.
2025-08-12 11:30:06 - app - INFO - Set status to PROCESSING for Document ID: 70117a22-97ce-48f8-9657-35e3ac7197f6
2025-08-12 11:31:36 - app - INFO - Successfully processed. Status set to COMPLETED for Document ID: 70117a22-97ce-48f8-9657-35e3ac7197f6
2025-08-12 11:42:40 - app - INFO - Triggering embedding process for Document ID: None.
2025-08-12 11:53:36 - app - INFO - Triggering embedding process for Document ID: None.
2025-08-12 11:54:32 - app - INFO - Source URL changed for Document ID: 7c073c4c-6868-4e20-accf-cee5566938ce. Deleting old chunks.
2025-08-12 11:54:32 - app - INFO - Triggering embedding process for Document ID: 7c073c4c-6868-4e20-accf-cee5566938ce.
2025-08-12 11:54:33 - app - INFO - Set status to PROCESSING for Document ID: 7c073c4c-6868-4e20-accf-cee5566938ce
2025-08-12 11:54:33 - app - ERROR - Status set to FAILED for Document ID: 7c073c4c-6868-4e20-accf-cee5566938ce
2025-08-12 11:58:01 - app - INFO - Source URL changed for Document ID: 7c073c4c-6868-4e20-accf-cee5566938ce. Deleting old chunks.
2025-08-12 11:58:02 - app - INFO - Triggering embedding process for Document ID: 7c073c4c-6868-4e20-accf-cee5566938ce.
2025-08-12 11:58:02 - app - INFO - Set status to PROCESSING for Document ID: 7c073c4c-6868-4e20-accf-cee5566938ce
2025-08-12 11:58:13 - app - INFO - Successfully processed. Status set to COMPLETED for Document ID: 7c073c4c-6868-4e20-accf-cee5566938ce
2025-08-12 12:12:39 - app - INFO - Source URL changed for Document ID: 7c073c4c-6868-4e20-accf-cee5566938ce. Deleting old chunks.
2025-08-12 12:12:39 - app - INFO - Triggering embedding process for Document ID: 7c073c4c-6868-4e20-accf-cee5566938ce.
2025-08-12 12:12:39 - app - INFO - Set status to PROCESSING for Document ID: 7c073c4c-6868-4e20-accf-cee5566938ce
2025-08-12 12:12:44 - app - INFO - Successfully processed. Status set to COMPLETED for Document ID: 7c073c4c-6868-4e20-accf-cee5566938ce
